Workbook

Sheet Included
A1: Title | B1: Authors | C1: Journal | D1: Year of Publication | E1: Citation | F1: Brief Summary | G1: Specific AI Tools mentioned | H1: Current Use of ML? | I1: Contribution to Bias? | J1: Source of Bias? | K1: Evidence of Bias? | L1: Benefits of AI | M1: Notes
A2: AI in Corrections | B2: Rowland, Matthew G., Amit Shah, and Ashit Chandra | C2: Federal Probation | D2: 2023 | E2: Rowland, Matthew G., Amit Shah, and Ashit Chandra. "AI in Corrections: The Basics and a Way to Experiment." Fed. Probation 87 (2023): 4. | F2: Explores the integration of AI into criminal justice to improve operational efficiency and decrease bias. Advocates for rigorous human oversight and staff training. | G2: LLM chatbots, LangChain, Deep Fakes | H2: No. Mentioned as a future possibility. | I2: Yes. | J2: Historical bias, bad actors developing AI | K2: None | L2: Improved efficiency, reducing human bias | M2: Advocates for a human-in-the-loop approach
A3: AI In Criminal Justice: Implications For Justice, Fairness, and Potential Biases | B3: Ramandeep Kaur | C3: Nyaayshastra Law Review | D3: 2023 | E3: Kaur, Ramandeep. "AI in Criminal Justice: Implications for Justice, Fairness, and Potential Biases." Nyaayshastra L. Rev. 4 (2023): 1. | F3: Compares the potential improvements that AI can make in criminal justice to the potential risks. Lists specific risks of bias and makes recomendations for fair practices. | G3: Strategic Subject List, COMPAS | H3: No. Mentions that "fiarness aware ML techniques" are recomended as a future practice. | I3: Yes. Bias based on race, gender, and socioeconomics | J3: Historical bias, | K3: 2018 Partnership on AI Study | L3: Improved efficiency, predictive accuracy, reducing human bias | M3: Advocates for regualtion and ethical guidelines paired with education for officers and judges.
A4: Algorithmic governance from the bottom up | B4: Hannah Bloch-Wehba | C4: BYU Law Review | D4: 2022 | E4: Bloch-Wehba, Hannah. "Algorithmic governance from the bottom up." BYU L. Rev. 48 (2022): 69. | F4: Analyses the place of private industry in "algorithmic governance", warning against a technocratic approach. | G4: Palantir, facial recognition, Rekognition, DataWorksPlus, NEC, Domain Awareness System, Ring, ShotSpotter, Vigilant Solutions, Stingray, Project GreenLight, Project Maven, TIA, Project Nimbus, Extreme Vetting Initiative, Anduril | H4: Yes. | I4: Yes. Reinforces existing hierarchies, targets populations, and gives the veneer of objectivity. | J4: Historical bias, institutional bias, exclusion of perspective, techinical disparities | K4: Amazon Rekognition identifies CA lawmakers as criminals, wrongful arrest of Robert Williams | L4: Streamlining services, maximizing limited resources, cost reduction, eleminating human flaws, improved predictive precision, balanced justice, interpretable reasoning, monitoring government, transparency | M4: Not limited to risk assesment, very wide review.
A5: Algorithmic risk assessment in the hands of humans | B5: Stevenson, Megan T., and Jennifer L. Doleac | C5: American Economic Journal: Economic Policy | D5: 2024 | E5: Stevenson, Megan T., and Jennifer L. Doleac. "Algorithmic risk assessment in the hands of humans." American Economic Journal: Economic Policy 16.4 (2024): 382-414. | F5: Examines integration of algorithmic risk assessment into judicial sentencin, with human discretion mediating technology. Finds that judges frequently override algorithmic recommendations. | G5: Virginia Criminal Sentencing Commission Risk Assessment, COMPAS, random forest, nonlinear SVM, Virginia Pretrial Risk Assessment | H5: Yes. The authors use random forest as a comparicon for Virginia's current assessment tool. | I5: Yes. | J5: Embedding disallowed variables like race and gender, institutional bias | K5: COMPAS. Shows that sentences would be 24% longer for young defendants based solely on risk assessment. Shows that judges give black defendants longer sentences than white even with the same risk score. Analysis in Virginia shows judges giving longer sentences to youth when influenced by risk assessment tools. | L5: Could reduce "statistical discrimination" | M5: Authors are testing their own ML model against an algorithmic system.
A6: Algorithmic risk governance: Big data analytics, race and information activism in criminal justice debates | B6: Hannah-Moffat, Kelly. | C6: Theoretical Criminology | D6: 2019 | E6: Hannah-Moffat, Kelly. "Algorithmic risk governance: Big data analytics, race and information activism in criminal justice debates." Theoretical Criminology 23.4 (2019): 453-470. | F6: Studies the rise of big data analytics as an alternative to established social science methodologies. Shows that algorithmic techniques can mask systemic racism. | G6: PrePol, facial recognition, license plate readers, COMPAS, LSI-R, Salient Factor Score, Florida Bail Algorithms | H6: Yes. Florida uses ML to determine bail amounts. PrePol employs ML. | I6: Yes. Mask systemic discrimination. Reporduces and rationalizes historical bias. | J6: Structural barriers become recorded as individual risk factors. Algorithms rationalise targeting margenalized groups. Software is developed without ethical conciousness. The "meaning" of recorded data can change over time. Large datasets can imply patterns where none exist. | K6: COMPAS flags black defendants twice as often. | L6: Improved efficiency and resource management. Expedited legal research. Objective and standardized decision making. Improved predictive accuracy. Greater oversight. Exposing systemic bias. Public transparency. | M6: Advocates for data-focused approaches to be applied alongside other methods of risk assessment.
A7: Algorithms and the individual in criminal law | B7: Jorgensen, Renée | C7: Canadian Journal of Philosophy | D7: 2022 | E7: Jorgensen, Renée. "Algorithms and the individual in criminal law." Canadian Journal of Philosophy 52.1 (2022): 61-77. | F7: Explores the possibility that predictive algorithms necesarily violate defendants' right to be treated as an individual. Argues that legal outcomes must be based on transparent variables in order to respect human autonomy. | G7: PredPol, HunchLab, Gotham from Palantir, Strategic Subject Initiative, Los Angeles Strategic Extraction and Restoration, Risk and Needs Assessment Tools, COMPAS, Arnold Public Safety Assessment, Virginia Pretrial Risk Assessment Instrument, Ohio Risk Assessment System, Correctional Assessment and Intervention System, Level of Service/Case Management Inventory, Strategic Subject List | H7: Yes. Pattern recognition. Employed in PredPol and HunchLab. Specifically mentions unsupervised and deep learning. | I7: Yes. Historiacal bias. | J7: Systems can learn proxy attributes for race. Big data methodologies are often trained on "dirty" or unreliable data. Can amplify or justify human bias. | K7: COMPAS has racially biased error rates. PrePol, HunchLab, and SSI have been trained on data that captures historical bias. | L7: Mitigating human bias. Detecting discrimination. Assessments can be highly tailored to the individual. Identifying high-crime hotspots. Preventing victimization. Detecting "white-collar" crime. | M7: Advocates for algorithmic tools to be applied alongside human judgement.
A8: Algorithms in practice: Comparing web journalism and criminal justice | B8: Christin, Angèle | C8: Big data & society | D8: 2017 | E8: Christin, Angèle. "Algorithms in practice: Comparing web journalism and criminal justice." Big data & society 4.2 (2017): 2053951717718855. | F8: Presents an ethnographic study of the simalarities between how algorithms are used in two institutions: journalism and criminal justice. Explores the interaction that people in these fields have with their algorithmic tools. | G8: Chartbeat (journalism), Omniture(journalism), COMPAS, Public Safety Assessment, case management systems | H8: No. ML is specifically discussed in cited sources from this article but not by the article itself. | I8: Yes. Masking historical bias and obscured subjectivity. "Discriminatory feedback loops" | J8: Gives "patina of objectivity" to human judgement. Output is only as good as the input, human misuse of tools may cause bias. Biased training data. Reinforcing inequality. Embedding race as a "group-based" variable. | K8: COMPAS. Clickbait driven by Chartbeat analytics. | L8: Neutral decision making. Increased transparency. Improved resource management. Real-time insights. | M8: Uses journalism as a leading indicator for changis in criminal justice caused by algorithmic analytics.
A9: Artificial intelligence, due process and criminal sentencing | B9: Villasenor, John, and Virginia Foggo | C9: Michigan State Law Review | D9: 2020 | E9: Villasenor, John, and Virginia Foggo. "Artificial intelligence, due process and criminal sentencing." Mich. St. L. Rev. (2020): 295. | F9: Examines the integration of AI into sentencing and the impact on the defendant's due process. Shows that proprietary algorithms create legal hurdles through secrecy and doubts of accuracy. | G9: COMPAS, Prisoner Assessment Tool Targeting Estimated Risk and Needs (PATTERN), Iowa Risk Revised, Level of Service Inventory-Revised, Risk and Needs Assessment | H9: Yes. Discusses five "generations" of algorithmic risk assessment with the last being ML. | I9: Yes. Historical bias is preserved and amplified. | J9: Projection of historical injustice. Biased training data. Proxy attributes. Lack of individualizaed sentencing. Failing to distinguish correlation and causation. | K9: COMPAS, ProPublica "Machine Bias" investigation. Proxy variables in the IRR. | L9: Objectivity. Bias reduction. Addressing disparities. Superhuman pattern recognition. Better judicial evaluation of specific cases. Resource management. | M9: Draws a meaningful distinct between algorithms and AI
A10: Assessing risk assessment in action | B10: Stevenson, Megan | C10: Minnesota Law Review | D10: 2018 | E10: Stevenson, Megan. "Assessing risk assessment in action." Minn. L. Rev. 103 (2018): 303. | F10: A rigourous emperical analysis of pretrial risk assessment tools using Kentucky as a case study. Shows that implementation of PSA did not improve efficiency, while expanding racial disparity. | G10: Public Safety Assessment, COMPAS, Post Conviction Risk Assessment, Virginia Pretrial Risk Assessment, Logistic Regression | H10: Yes. Distinguishes ML from "checklist style" assessments. | I10: Yes. | J10: Biased training data. Proxy attributes. Over policing of minority neighborhoods. Displacement of subjective judgement. Trade-offs in fairness. | K10: COMPAS, ProPublica "Machine Bias" investigation. Kentucky racial gap expansion | L10: Better predictive performance than intuitive methods. Decreasing detention rates. Resource management. Minimizing human bias. Standardization. | M10: Argues that disparate false positive rates in assessment tool is not a measure of racial bias. Generally unsupportive of algorithmic risk assessment.
A11: Bail or jail? Judicial versus algorithmic decision-making in the pretrial system | B11: Elyounes, Doaa Abu | C11: The Columbia Science and Technology Law Review | D11: 2020 | E11: Elyounes, Doaa Abu. "Bail or jail? Judicial versus algorithmic decision-making in the pretrial system." CoLuM. SCi. & TECH. L. REv. 21 (2019): 376. | F11: Investigates the use of pretrial actuarial risk assessment tools, comparing traditional regression techniques to modern ML techniques. Examines the trade-off between rationalized decision making and preserving historical disparities. | G11: Pretrial Risk Assessment, Public Safety Assessment, Virginia Pretrial Risk Assessment Instrument, Colorado Pretrial Risk Assessment Tool, Ohio Pretrial Assessment Tool (PAT), COMPAS, The Kleinberg et al. Tool, Vera Point Scale | H11: Yes. Distinguishes ML from regression analysis but claims that there are more simalarities than differences between the two. Specifically references unsupervised learning. | I11: Yes. Racial and socio-economic bias. Ratchet effect -> the system focuses on overrepresented individuals in courts. | J11: Biased and discriminatory training data. Overrepresentation of black defendants. Proxy variables. Human interpretation of metrics. Black box algorithms. | K11: COMPAS and ProPublica. Kentucky Judicial Interaction Study. Denver CPAT Home Ownership Proxy. The Ohio PAT Validity Study. Summarized in Table 3. | L11: Enhanced individualization. Improved predictive accuracy. Reducing detention by 41.9% without increasing crime rates. Accelerating the rate of social reform. Faster revalidation of risk assessment tools. | M11: Great rundown of commonly used tools in Section 3. "...none of the risk assessment tools currently in use operate like a black box." Section 2.C.3
A12: Bias in, bias out | B12: Mayson, Sandra G. | C12: The Yale Law Journal | D12: 2018 | E12: Mayson, Sandra G. "Bias in, bias out." YAle lJ 128 (2018): 2218. | F12: Analyses the racial impacts of algorithmic risk assessment and outlines strategies for fair implementation. | G12: COMPAS, Post Conviction Risk Assessment, Kleinberg et al. Tool | H12: Yes. Mentions Durham-Hart model by name. Distinguishes between checklist instruments and ML algorithms. | I12: Yes. "The premise of prediction is that, absent intervention, history will repeat itself." | J12: Veneer of objectivity. Preservance historical disparities. Equality trade-offs. Proxy variables. | K12: COMPAS, DOJ Investigations: Ferguson, Baltimore, and New Orleans, The Kentucky Judicial Interaction Study, The Richard Berk Juvenile Justice Study | L12: Operational efficiency. Predictive accuracy. Removing irrational biases. "...crystalline image of visible, quantified data...", identifies causes of disparity, targeting social support, needs-oriented responses, reentry models | M12: Contains specific recomendations to improve the racial impacts of algorithmic risk assessment.
A13: Citizen Decisions and Machine Predictions: Coethnicity, Artificial Intelligence and Co-Production | B13: Anastasopoulos, L. Jason, and Micah Gell-Redman | C13: New England Area Political Psychology Meeting | D13: 2024 | E13: Anastasopoulos, L. Jason, and Micah Gell-Redman. "Citizen Decisions and Machine Predictions: Coethnicity, Artificial Intelligence and Co-Production." (2024). | F13: Studies the ways that social identity and coethnicity affect how AI-generated risk assessments are interpredted. Uses discrete choice model to investigate the trust that groups place in AI risk scores. | G13: COMPAS, the random forest algorithm, predictive policing tools, social credit scoring, Real-Time Crime Centers | H13: Yes. Recommender systems are used as an example. Random forest is used experimentally to classify synthetic high- and low-risk offenders. | I13: No. The paper argues that AI can and may contribute to, sustain, and mask bias but does not specifically state that AI tools currently in use are contributing to judicial bias. | J13: Historical bias. Amplifying trends involving misidentifying some individuals as dangerous. Confirmation bias. "Decoupling" of trust by individuals who are used to being treated unfairly. | K13: The ProPublica Broward County Dataset, COMPAS, “‘Just like I thought’: Street-level bureaucrats trust AI recommendations if they confirm their professional judgment.” | L13: Online platforms can enable mutual trust between individuals, informed decision making, aiding rapid police responses, supporting partnerships between community and police | M13: Good links to recent studies.
... A57: Algorithmic Decision Making and the Cost of Fairness | B57: Corbett-Davies, Sam, Emma Pierson, Avi Feller, Sharad Goel, and Aziz Huq | C57: Proceedings of the 23rd acm sigkdd international conference on knowledge discovery and data mining | D57: 2017 | E57: Corbett-Davies, Sam, Emma Pierson, Avi Feller, Sharad Goel, and Aziz Huq. "Algorithmic decision making and the cost of fairness." In Proceedings of the 23rd acm sigkdd international conference on knowledge discovery and data mining, pp. 797-806. 2017. | F57: Analyzes the tradeoffs in fairness in risk assessment. Shows that risk prediction algorithms unconstrained by fairness require race-specific thresholds while constrained algorithms do not. | G57: COMPAS. Logistic regression. Berk Risk Assessment Tool. | H57: Yes. ML is not specifically discussed by name. Does discuss predictive tools, and specifically mentions logistic regression, which is an ML tool. | I57: Yes. Racial bias and the unequal impact of "colorblind" algorithms. | J57: Bias in historial data. Algorithms that are optimized for public safety rather than fairness. Tradeoffs. | K57: COMPAS and Broward County. | L57: Improving efficiency. Improving equity. Maximizing public safety. Less individual burden. Reducing incarceration. | M57: "Statistical risk assessment has been used in criminal justice for nearly one hundred years, dating back to parole decisions in the1920s" "In a randomized controlled trial, the Philadelphia Adult Probation and Parole Department evaluated the e_x0082_fectiveness of a risk assessment tool developed by Berk et al. [10], and found the tool reduced the burden on parolees without signi_x0080_cantly increasing rates of re-f_x0082_ense"

Sheet Excluded Before Retrieval
A1: Title | B1: Authors | C1: Reason | D1: Located In
A2: “Why Do I Care What’s Similar?” Probing Challenges in AI-Assisted Child Welfare Decision-Making through Worker-AI Interface Design Concepts | B2: Kawakami, Anna and Sivaraman, Venkatesh and Stapleton, Logan and Cheng, Hao-Fei and Perer, Adam and Wu, Zhiwei Steven and Zhu, Haiyi and Holstein, Kenneth | C2: Focus on Juveniles | D2: ACM Digital Library
A3: Accuracy and racial biases of recidivism prediction instruments | B3: Julia J. Dressel | C3: Student Thesis | D3: Google Scholar
A4: Addressing Delayed Justice in the Indian Legal System through AI Integration | B4: Joshi, Kavita Ajay and Mathur, Priya and Koranga, Ravindra and Singh, Lalit | C4: Non-US | D4: ACM Digital Library
A5: Addressing Procedural and Tooling Challenges in Juvenile Justice: Towards Responsible and Human-Centered Design | B5: S Gilman, Elizabeth and Flathmann, Christopher and Dixon, Emma | C5: Focus on Juveniles | D5: ACM Digital Library
A6: Algorithmic Fairness and Structural Injustice: Insights from Feminist Political Philosophy | B6: Kasirzadeh, Atoosa | C6: Not courtwoom risk-assessment focused | D6: ACM Digital Library
A7: Algorithmic Governance and Governance of Algorithms | B7: M Ebers, MC Gamito | C7: Textbook | D7: Google Scholar
A8: Algorithmic governance: Technology, knowledge and power | B8: Peeters, Rik, and Marc Schuilenburg | C8: Textbook Chapter | D8: Google Scholar
A9: Algorithms and Recidivism: A Multi-disciplinary Systematic Review | B9: Scaria, Arul George and Subramanian, Vidya and George, Nevin K and Sengupta, Nandana | C9: Summarizes Other Work | D9: ACM Digital Library
A10: Assessing risk of recidivism among juvenile offenders: The development and validation of the recidivism risk instrument | B10: LR Williams, CW LeCroy, JP Vivian | C10: Focus on Juveniles | D10: Google Scholar
A11: Beyond Predictive Algorithms in Child Welfare | B11: Moon, Erina Seh-Young and Saxena, Devansh and Maharaj, Tegan and Guha, Shion | C11: Focus on Juveniles | D11: ACM Digital Library
A12: Can Fairness be Automated? Guidelines and Opportunities for Fairness-aware AutoML | B12: Weerts, Hilde and Pfisterer, Florian and Feurer, Matthias and Eggensperger, Katharina and Bergman, Edward and Awad, Noor and Vanschoren, Joaquin and Pechenizkiy, Mykola and Bischl, Bernd and Hutter, Frank | C12: Not courtwoom risk-assessment focused | D12: ACM Digital Library
... A64: Transparency, Governance and Regulation of Algorithmic Tools Deployed in the Criminal Justice System: a UK Case Study | B64: Zilka, Miri and Sargeant, Holli and Weller, Adrian | C64: Non-US | D64: ACM Digital Library

Sheet Excluded After Retrieval
A1: Title | B1: Authors | C1: Reason | D1: Located In
A2: A Case for Humans-in-the-Loop: Decisions in the Presence of Erroneous Algorithmic Scores | B2: De-Arteaga, Fogliato, Chouldechova | C2: Focus on Juveniles | D2: Google Scholar | F2: Juveniles | G2: =countif(C:C, "*juvenile*") -> 1
A3: A Comparative User Study of Human Predictions in Algorithm-Supported Recidivism Risk Assessment | B3: M Portela, C Castillo, S Tolan, M Karimi-Haghighi, AA Pueyo | C3: Non-US | D3: Google Scholar | F3: Non-US | G3: =countif(C:C, "*non-us*") -> 17
A4: Abolish! Against the Use of Risk Assessment Algorithms at Sentencing in the US Criminal Justice System | B4: Katia Schwerzmann | C4: Persuasive | D4: Google Scholar | F4: Persuasive | G4: =countif(C:C, "*persuasive*") -> 16
A5: Algorithmic decision making and issues of criminal justice–A general approach | B5: Krisztina KARSAI | C5: Non-US | D5: Google Scholar | F5: Not RA | G5: =countif(C:C, "*risk-assessment focused*") -> 10
A6: Algorithmic Fairness From the Perspective of Legal Anti-Discrimination Principles | B6: Keswani, Vijay and Celis, L. Elisa | C6: Not courtwoom risk-assessment focused | D6: ACM Digital Library | F6: Not AI | G6: =countif(C:C, "*not ai*") -> 2
A7: Algorithmic long-term unemployment risk assessment in use: Counselors' perceptions and use practices | B7: Leid Zejnilović | C7: Not courtwoom risk-assessment focused | D7: Google Scholar | F7: No peer review | G7: =countif(C:C, "*peer*") -> 1
A8: Algorithmic risk assessments can alter human decision-making processes in high-stakes government contexts | B8: B Green, Y Chen | C8: Not courtwoom risk-assessment focused | D8: Google Scholar, ACM Digital Library
A9: Bias in Criminal Risk Scores is Mathematically Inevitable, Researchers Say | B9: Julie Angwin and Jeff Larson | C9: Persuasive | D9: Google Scholar | F9: Multiple | G9: =countif(C:C, "*,*") -> 4
A10: Challenge accepted? A critique of the 2021 National Institute of Justice recidivism forecasting challenge | B10: T Jegede, MK Gerchick, AS Mathai | C10: Summarizes Other Work | D10: Google Scholar, ACM Digital Library | F10: Total | G10: =SUM(G2:G8) - G9 -> 43
A11: Damned lies & criminal sentencing using evidence-based tools | B11: J Lightbourne | C11: Persuasive | D11: Google Scholar
A12: Disambiguating Algorithmic Bias: From Neutrality to Justice | B12: Edenberg, Elizabeth and Wood, Alexandra | C12: Not courtwoom risk-assessment focused | D12: ACM Digital Library
A13: Disparities in the pretrial process: Race, ethnicity, and citizenship | B13: Casey, William M., Jennifer E. Copp, and Stephen Demuth | C13: Not AI focused | D13: Google Scholar
A14: Enhancing a recidivism prediction tool with machine learning: effectiveness and algorithmic fairness | B14: Karimi-Haghighi, Marzieh, and Carlos Castillo | C14: Non-US | D14: Google Scholar
A15: Ethics and trustworthiness of AI for predicting the risk of recidivism: A systematic literature review | B15: MM Farayola, I Tal, R Connolly, T Saber | C15: Summarizes Other Work | D15: Google Scholar
A16: Evidence-based sentencing and the scientific rationalization of discrimination | B16: Starr, Sonja B | C16: Persuasive | D16: Google Scholar
A17: Evidence-Based Sentencing: Risks and Opportunities | B17: Westermann, Hannes | C17: Non-US | D17: Google Scholar
A18: Exploring algorithmic governance: The AI Act and new realities for criminal justice, and fundamental rights | B18: Anastasopoulou, Melina | C18: Non-US | D18: Google Scholar
A19: EXPLORING RECIDIVISM THROUGH BAYESIAN SURVIVAL MODELS: A PARAMETRIC APPROACH WITH RSTAN | B19: F Ashraf, M Parvej, AA Khan | C19: Non-US | D19: Google Scholar
A20: Fairness of AI in predicting the risk of recidivism: Review and phase mapping of AI fairness techniques | B20: Farayola, Michael Mayowa, Irina Tal, Bendechache Malika, Takfarinas Saber, and Regina Connolly | C20: Non-US | D20: ACM Digital Library
A21: Forks over knives: Predictive inconsistency in criminal justice algorithmic risk assessment tools | B21: Travis Greene, Galit Shmueli, Jan Fell, Ching-Fu Lin, Han-Wei Liu | C21: Persuasive, Non-US | D21: Google Scholar
A22: From Margins to the Table: Charting the Potential for Public Participatory Governance of Algorithmic Decision Making | B22: Eslami, Motahhare and Fox, Sarah and Shen, Hong and Fan, Bobbie and Lin, Yu-Ru and Farzan, Rosta and Schwanke, Beth | C22: Not courtwoom risk-assessment focused | D22: ACM Digital Library
... A50: Why predictive algorithms are so risky for public sector bodies | B50: M Waller, P Waller | C50: Persuasive | D50: Google Scholar

Sheet Text Analysis
A1: Total included sources: | B1: =COUNTA(Included!A:A) - 1 -> 56
A2: Total excluded before retrieval: | B2: =COUNTA('Excluded Before Retrieval'!A:A) - 1 -> 63
A3: Total excluded after retrieval: | B3: =COUNTA('Excluded After Retrieval'!A:A) - 1 -> 49
A4: Total sources: | B4: =SUM(B1:B3) -> 168
A5: Unique journals: | B5: =IFERROR(__xludf.DUMMYFUNCTION("COUNTUNIQUE(Included!C:C)-1"),54.0) -> 54
A7: Year of publication | B7: 2015 | C7: 2016 | D7: 2017 | E7: 2018 | F7: 2019 | G7: 2020 | H7: 2021 | I7: 2022 | J7: 2023 | K7: 2024 | L7: 2025 | M7: 2026
B8: =COUNTIF(Included!$D:$D, "=2015") -> 1 | C8: =COUNTIF(Included!$D:$D, "=2016") -> 2 | D8: =COUNTIF(Included!$D:$D, "=2017") -> 8 | E8: =COUNTIF(Included!$D:$D, "=2018") -> 8 | F8: =COUNTIF(Included!$D:$D, "=2019") -> 6 | G8: =COUNTIF(Included!$D:$D, "=2020") -> 7 | H8: =COUNTIF(Included!$D:$D, "=2021") -> 8 | I8: =COUNTIF(Included!$D:$D, "=2022") -> 5 | J8: =COUNTIF(Included!$D:$D, "=2023") -> 6 | K8: =COUNTIF(Included!$D:$D, "=2024") -> 3 | L8: =COUNTIF(Included!$D:$D, "=2025") -> 2 | M8: =COUNTIF(Included!$D:$D, "=2026") -> 0
A9: Check sum: | B9: =SUM(B8:M8) -> 56
A11: AI does contribute to bias: | B11: =countif(Included!I:I, "yes*") -> 44 | C11: Percentage: | D11: =DIVIDE(B11,B$1) -> 0.78571429 | E11: =ROUND(D11, 2) -> 0.79
A12: AI does not: | B12: =countif(Included!I:I, "no*") -> 12 | D12: =DIVIDE(B12,B$1) -> 0.21428571 | E12: =ROUND(D12, 2) -> 0.21
A13: Check sum: | B13: =sum(B11:B12) -> 56
A15: ML in use: | B15: =countif(Included!H:H, "yes*") -> 42 | C15: Percentage: | D15: =DIVIDE(B15,B$1) -> 0.75 | E15: =ROUND(D15, 2) -> 0.75
A16: ML not used: | B16: =countif(Included!H:H, "no*") -> 14 | D16: =DIVIDE(B16,B$1) -> 0.25 | E16: =ROUND(D16, 2) -> 0.25
A17: Check sum: | B17: =sum(B15:B16) -> 56
A19: COMPAS used as example: | B19: =countif(Included!K:K, "*compas*") -> 36 | C19: Percentage: | D19: =DIVIDE(B19,B$1) -> 0.64285714 | E19: =ROUND(D19, 2) -> 0.64
A20: COMPAS not used: | B20: =countif(Included!K2:K56, "<>*compas*") -> 20 | D20: =DIVIDE(B20,B$1) -> 0.35714286 | E20: =ROUND(D20, 2) -> 0.36
A21: Check sum: | B21: =sum(B19:B20) -> 56
A23: Tools Mentioned: | B23: COMPAS | C23: SSL | D23: facial recognition | E23: Virginia Pretrial Risk Assessment | F23: random forest | G23: SVMs | H23: PredPol | I23: license plate readers | J23: LSI-R | K23: Salient Factor Score | L23: HunchLab | M23: Gotham
B24: =countif(Included!G:G, "*compas*") -> 37 | C24: =sum(countif(Included!G:G, "*strategic subject list*"), countif(Included!G:G, "*SSL*")) -> 4 | D24: 7 | E24: =sum(countif(Included!G:G, "*Virginia Pretrial Risk Assessment*"), countif(Included!G:G, "*VPRA*")) -> 8 | F24: =countif(Included!G:G, "*random forest*") -> 6 | G24: =countif(Included!G:G, "*SVM*") -> 3 | H24: =countif(Included!G:G, "*predpol*") -> 6 | I24: =countif(Included!G:G, "*license plate*") -> 1 | J24: =sum(countif(Included!G:G, "*level of service*"), countif(Included!G:G, "*lsi*")) -> 11 | K24: =sum(countif(Included!G:G, "*salient factor*"), countif(Included!G:G, "*SFS*")) -> 3 | L24: =countif(Included!G:G, "*hunchlab*") -> 3 | M24: =countif(Included!G:G, "*gotham*") -> 1
B26: PSA | C26: PATTERN | D26: logistic regression | E26: Colorado Pretrial Risk Assessment Tool | F26: Ohio Pretrial Assessment Tool | G26: The Kleinberg Tool | H26: Vera Point Scale | I26: Post Conviction Risk Assessment | J26: Montana Offender and Reenty Risk Assessment Tool | K26: gradient boosting | L26: NLP | M26: NER
B27: =sum(countif(Included!G:G, "*public safety assessment*"), countif(Included!G:G, "*PSA*")) -> 19 | C27: =sum(countif(Included!H:H, "*Prisoner Assessment Tool Targeting Estimated Risk and Needs*"), countif(Included!H:H, "*PATTERN*")) -> 2 | D27: =countif(Included!G:G, "*logistic regression*") -> 7 | E27: =sum(countif(Included!G:G, "*Virginia Pretrial Risk Assessment*"), countif(Included!G:G, "*VPRA*")) -> 8 | F27: =sum(countif(Included!G:G, "*Ohio Pretrial Assessment Tool *"), countif(Included!G:G, "*(PAT)*")) -> 2 | G27: =countif(Included!G:G, "*kleinberg*") -> 4 | H27: =countif(Included!G:G, "*vera*") -> 2 | I27: =sum(countif(Included!G:G, "*post conviction risk assessment*"), countif(Included!G:G, "*pcra*")) -> 4 | J27: =sum(countif(Included!G:G, "*Montana Offender and Reenty Risk Assessment Tool*"), countif(Included!G:G, "*morrat*")) -> 1 | K27: 4 | L27: 1 | M27: 1
A29: Top 6 RAs: | B29: COMPAS | C29: PSA | D29: LSI-R | E29: Virginia Pretrial Risk Assessment | F29: Colorado Pretrial Risk Assessment Tool | G29: Post Conviction Risk Assessment
A30: Count | B30: =B24 -> 37 | C30: =B27 -> 19 | D30: =J24 -> 11 | E30: =E24 -> 8 | F30: =E27 -> 8 | G30: =I27 -> 4
A31: Percent | B31: =round(B30/$B$1, 2) -> 0.66 | C31: =round(C30/$B$1, 2) -> 0.34 | D31: =round(D30/$B$1, 2) -> 0.2 | E31: =round(E30/$B$1, 2) -> 0.14 | F31: =round(F30/$B$1, 2) -> 0.14 | G31: =round(G30/$B$1, 2) -> 0.07
A32: Policing Tools: | B32: PredPol | C32: facial recognition | D32: SSL | E32: license plate readers
A33: Count | B33: =H24 -> 6 | C33: =D24 -> 7 | D33: =C24 -> 4 | E33: =I24 -> 1
A34: Percent | B34: =round(B33/$B$1, 2) -> 0.11 | C34: =round(C33/$B$1, 2) -> 0.13 | D34: =round(D33/$B$1, 2) -> 0.07 | E34: =round(E33/$B$1, 2) -> 0.02
A35: AI research tools: | B35: random forest | C35: logistic regression | D35: SVMs | E35: gradient boosting
A36: Count | B36: =F24 -> 6 | C36: =D27 -> 7 | D36: =G24 -> 3 | E36: 5
A37: Percent | B37: =round(B36/$B$1, 2) -> 0.11 | C37: =round(C36/$B$1, 2) -> 0.13 | D37: =round(D36/$B$1, 2) -> 0.05 | E37: =round(E36/$B$1, 2) -> 0.09
A39: Benefits of AI | B39: Efficiency | C39: Reduced Bias | D39: Better Predictions | E39: Transparency | F39: Objectivity | G39: Individuation | H39: Reducing Crime | I39: Reducing Incarceration | J39: Social/Justice Reform | K39: Eleminate Bail
A40: Count | B40: 38 | C40: 34 | D40: 26 | E40: 14 | F40: 17 | G40: 7 | H40: 8 | I40: 16 | J40: 12 | K40: 7
A41: Percent | B41: =B40/$B$1 -> 0.67857143 | C41: =C40/$B$1 -> 0.60714286 | D41: =D40/$B$1 -> 0.46428571 | E41: =E40/$B$1 -> 0.25 | F41: =F40/$B$1 -> 0.30357143 | G41: =G40/$B$1 -> 0.125 | H41: =H40/$B$1 -> 0.14285714 | I41: =I40/$B$1 -> 0.28571429 | ... K41: =K40/$B$1 -> 0.125
A42: Rounded Percent | B42: =ROUND(B41, 2) -> 0.68 | C42: =ROUND(C41, 2) -> 0.61 | D42: =ROUND(D41, 2) -> 0.46 | E42: =ROUND(E41, 2) -> 0.25 | F42: =ROUND(F41, 2) -> 0.3 | G42: =ROUND(G41, 2) -> 0.13 | H42: =ROUND(H41, 2) -> 0.14 | I42: =ROUND(I41, 2) -> 0.29 | ... K42: =ROUND(K41, 2) -> 0.13
A44: Yes bias and used COMPAS | B44: =COUNTIFS(Included!I$2:I$57, "yes*", Included!K$2:K$57, "*compas*") -> 32 | C44: =ROUND(B44/(B44+B45), 2) -> 0.73 | D44: % of yeses
A45: Yes bias without COMPAS | B45: =COUNTIFS(Included!I$2:I$57, "yes*", Included!K$2:K$57, "<>*compas*") -> 12 | C45: =ROUND(B45/(B44+B45), 2) -> 0.27 | D45: % of yeses
A46: No bias and used COMPAS | B46: =COUNTIFS(Included!I$2:I$57, "no*", Included!K$2:K$57, "*compas*") -> 4 | C46: =ROUND(B46/(B46+B47), 2) -> 0.33 | D46: % of nos
A47: No bias without COMPAS | B47: =COUNTIFS(Included!I$2:I$57, "no*", Included!K$2:K$57, "<>*compas*") -> 8 | C47: =ROUND(B47/(B46+B47), 2) -> 0.67 | D47: % of nos
A48: Checksum: | B48: =SUM(B44:B47) -> 56 | C48: =B48/B1 -> 1 | D48: % of all
A50: Sources of Bias | B50: Training Data | C50: Actions by Developers | D50: Institutional Bias | E50: Proxy Variables | F50: Rationalizing Bias | G50: Data Size | H50: Removing Human Judgement | I50: Definitions of Fairness | J50: Human Interpretation | K50: Black Boxing | L50: Tool Calibration | M50: Aglorithmic Bias
...
